<?xml version="1.0" ?>
<!-- =================================================================================== -->
<!-- |    This document was autogenerated by xacro from /home/igor/Projects/airstand-primary/ros/simvis/models/airstand/platform/platform.sdf.xacro | -->
<!-- |    EDITING THIS FILE BY HAND IS NOT RECOMMENDED                                 | -->
<!-- =================================================================================== -->
<sdf version="1.10">
  <model canonical_link="base" name="platform">
    <link name="base">
      <visual name="base_visual">
        <pose>0 0 -0.245 0 0 0</pose>
        <geometry>
          <mesh>
            <uri>file:///home/igor/Projects/airstand-primary/ros/simvis/models/airstand/platform/platform.stl</uri>
            <scale>0.01 0.01 0.01</scale>
          </mesh>
        </geometry>
        <material>
          <diffuse>0 0 1</diffuse>
          <ambient>0 0 0.5</ambient>
          <specular>0 0 0.5</specular>
        </material>
      </visual>
      <collision name="base_collision">
        <geometry>
          <cylinder>
            <length>0.59</length>
            <radius>0.15</radius>
          </cylinder>
        </geometry>
      </collision>
      <inertial>
        <mass>3.3</mass>
        <inertia>
          <ixx>0.334</ixx>
          <ixy>0</ixy>
          <ixz>0</ixz>
          <iyy>0.334</iyy>
          <iyz>0</iyz>
          <izz>0.0017</izz>
        </inertia>
      </inertial>
    </link>
    <link name="prop_left">
      <pose relative_to="base">0 0.17 -0.12999999999999998 0 0 0</pose>
      <inertial>
        <mass>0.1</mass>
        <inertia>
          <ixx>0.334</ixx>
          <ixy>0</ixy>
          <ixz>0</ixz>
          <iyy>0.334</iyy>
          <iyz>0</iyz>
          <izz>0.0017</izz>
        </inertia>
      </inertial>
      <visual name="prop_prop_left_vis">
        <geometry>
          <box>
            <size>0.01 0.1 0.1</size>
          </box>
        </geometry>
        <material>
          <diffuse>1 0 0</diffuse>
        </material>
      </visual>
    </link>
    <joint name="prop_left_joint" type="revolute">
      <parent>base</parent>
      <child>prop_left</child>
      <axis>
        <xyz>1 0 0</xyz>
      </axis>
    </joint>
    <plugin filename="gz-sim-thruster-system" name="gz::sim::systems::Thruster">
      <joint_name>prop_left_joint</joint_name>
      <thrust_coefficient>1</thrust_coefficient>
      <fluid_density>1.225</fluid_density>
      <propeller_diameter>0.2</propeller_diameter>
      <p_gain>0</p_gain>
      <d_gain>0</d_gain>
      <i_gain>0</i_gain>
    </plugin>
    <link name="prop_right">
      <pose relative_to="base">0 -0.17 -0.12999999999999998 0 0 0</pose>
      <inertial>
        <mass>0.1</mass>
        <inertia>
          <ixx>0.334</ixx>
          <ixy>0</ixy>
          <ixz>0</ixz>
          <iyy>0.334</iyy>
          <iyz>0</iyz>
          <izz>0.0017</izz>
        </inertia>
      </inertial>
      <visual name="prop_prop_right_vis">
        <geometry>
          <box>
            <size>0.01 0.1 0.1</size>
          </box>
        </geometry>
        <material>
          <diffuse>1 0 0</diffuse>
        </material>
      </visual>
    </link>
    <joint name="prop_right_joint" type="revolute">
      <parent>base</parent>
      <child>prop_right</child>
      <axis>
        <xyz>1 0 0</xyz>
      </axis>
    </joint>
    <plugin filename="gz-sim-thruster-system" name="gz::sim::systems::Thruster">
      <joint_name>prop_right_joint</joint_name>
      <thrust_coefficient>1</thrust_coefficient>
      <fluid_density>1.225</fluid_density>
      <propeller_diameter>0.2</propeller_diameter>
      <p_gain>0</p_gain>
      <d_gain>0</d_gain>
      <i_gain>0</i_gain>
    </plugin>
  </model>
</sdf>
